2024-11-02 17:43:01,854 INFO    Thread-30 (_run_job):56530 [wandb_setup.py:_flush():79] Current SDK version is 0.18.5
2024-11-02 17:43:01,856 INFO    Thread-30 (_run_job):56530 [wandb_setup.py:_flush():79] Configure stats pid to 56530
2024-11-02 17:43:01,856 INFO    Thread-30 (_run_job):56530 [wandb_setup.py:_flush():79] Loading settings from /Users/abhinavraundhal/.config/wandb/settings
2024-11-02 17:43:01,856 INFO    Thread-30 (_run_job):56530 [wandb_setup.py:_flush():79] Loading settings from /Users/abhinavraundhal/Documents/sem_5/SMAI/Assignments/All_Assignments/smai-m24-assignments-Abhinav7R/assignments/4/wandb/settings
2024-11-02 17:43:01,856 INFO    Thread-30 (_run_job):56530 [wandb_setup.py:_flush():79] Loading settings from environment variables: {'project': 'SMAI_ASG_4_CNN_AutoEncoder', 'entity': 'abhinav7', 'root_dir': '/Users/abhinavraundhal/Documents/sem_5/SMAI/Assignments/All_Assignments/smai-m24-assignments-Abhinav7R/assignments/4', 'run_id': '7pkcnvs0', 'sweep_param_path': '/Users/abhinavraundhal/Documents/sem_5/SMAI/Assignments/All_Assignments/smai-m24-assignments-Abhinav7R/assignments/4/wandb/sweep-edh0epfy/config-7pkcnvs0.yaml', 'sweep_id': 'edh0epfy'}
2024-11-02 17:43:01,856 INFO    Thread-30 (_run_job):56530 [wandb_setup.py:_flush():79] Applying setup settings: {'mode': None, '_disable_service': None}
2024-11-02 17:43:01,857 INFO    Thread-30 (_run_job):56530 [wandb_setup.py:_flush():79] Inferring run settings from compute environment: {'program': '<python with no main file>'}
2024-11-02 17:43:01,857 INFO    Thread-30 (_run_job):56530 [wandb_init.py:_log_setup():534] Logging user logs to /Users/abhinavraundhal/Documents/sem_5/SMAI/Assignments/All_Assignments/smai-m24-assignments-Abhinav7R/assignments/4/wandb/run-20241102_174301-7pkcnvs0/logs/debug.log
2024-11-02 17:43:01,857 INFO    Thread-30 (_run_job):56530 [wandb_init.py:_log_setup():535] Logging internal logs to /Users/abhinavraundhal/Documents/sem_5/SMAI/Assignments/All_Assignments/smai-m24-assignments-Abhinav7R/assignments/4/wandb/run-20241102_174301-7pkcnvs0/logs/debug-internal.log
2024-11-02 17:43:01,857 INFO    Thread-30 (_run_job):56530 [wandb_init.py:_jupyter_setup():480] configuring jupyter hooks <wandb.sdk.wandb_init._WandbInit object at 0x160c13aa0>
2024-11-02 17:43:01,857 INFO    Thread-30 (_run_job):56530 [wandb_init.py:init():621] calling init triggers
2024-11-02 17:43:01,858 INFO    Thread-30 (_run_job):56530 [wandb_init.py:init():628] wandb.init called with sweep_config: {'epochs': 10, 'lr': 0.001, 'optimizer_type': 'adam'}
config: {}
2024-11-02 17:43:01,858 INFO    Thread-30 (_run_job):56530 [wandb_init.py:init():671] starting backend
2024-11-02 17:43:01,858 INFO    Thread-30 (_run_job):56530 [wandb_init.py:init():675] sending inform_init request
2024-11-02 17:43:01,863 INFO    Thread-30 (_run_job):56530 [backend.py:_multiprocessing_setup():104] multiprocessing start_methods=spawn,fork,forkserver, using: spawn
2024-11-02 17:43:01,864 INFO    Thread-30 (_run_job):56530 [wandb_init.py:init():688] backend started and connected
2024-11-02 17:43:01,873 INFO    Thread-30 (_run_job):56530 [wandb_run.py:_config_callback():1390] config_cb None None {'epochs': 10, 'lr': 0.001, 'optimizer_type': 'adam'}
2024-11-02 17:43:01,885 INFO    Thread-30 (_run_job):56530 [wandb_run.py:_label_probe_notebook():1342] probe notebook
2024-11-02 17:43:01,888 INFO    Thread-30 (_run_job):56530 [wandb_init.py:init():783] updated telemetry
2024-11-02 17:43:01,915 INFO    Thread-30 (_run_job):56530 [wandb_init.py:init():816] communicating run to backend with 90.0 second timeout
2024-11-02 17:43:02,044 INFO    Thread-18 (_run_job):56530 [wandb_run.py:_restore():2408] restore
2024-11-02 17:43:02,044 INFO    Thread-18 (_run_job):56530 [wandb_run.py:_restore():2414] restore done
2024-11-02 17:43:02,044 ERROR   Thread-18 (_run_job):56530 [wandb_run.py:_atexit_cleanup():2447] Problem finishing run
Traceback (most recent call last):
  File "/var/folders/fp/g6h334cs71j2vl505scsq0dh0000gn/T/ipykernel_56530/314847199.py", line 14, in sweep_train
    test_loss = test_model(model, test_loader, nn.MSELoss(), device=device)
                ^^^^^^^^^^^^^^^^^^^^^^^^^^^^^^^^^^^^^^^^^^^^^^^^^^^^^^^^^^^
  File "/var/folders/fp/g6h334cs71j2vl505scsq0dh0000gn/T/ipykernel_56530/698533762.py", line 11, in test_model
    print(f"Test MSE Loss: {test_loss:.4f}")
  File "/opt/anaconda3/envs/smai_env/lib/python3.12/site-packages/wandb/sdk/lib/redirect.py", line 645, in write
    self._old_write(data)
  File "/opt/anaconda3/envs/smai_env/lib/python3.12/site-packages/ipykernel/iostream.py", line 694, in write
    self._schedule_flush()
  File "/opt/anaconda3/envs/smai_env/lib/python3.12/site-packages/ipykernel/iostream.py", line 590, in _schedule_flush
    self.pub_thread.schedule(_schedule_in_thread)
  File "/opt/anaconda3/envs/smai_env/lib/python3.12/site-packages/ipykernel/iostream.py", line 267, in schedule
    self._event_pipe.send(b"")
  File "/opt/anaconda3/envs/smai_env/lib/python3.12/site-packages/zmq/sugar/socket.py", line 696, in send
    return super().send(data, flags=flags, copy=copy, track=track)
           ^^^^^^^^^^^^^^^^^^^^^^^^^^^^^^^^^^^^^^^^^^^^^^^^^^^^^^^
  File "zmq/backend/cython/socket.pyx", line 742, in zmq.backend.cython.socket.Socket.send
  File "zmq/backend/cython/socket.pyx", line 783, in zmq.backend.cython.socket.Socket.send
  File "zmq/backend/cython/socket.pyx", line 138, in zmq.backend.cython.socket._check_closed
zmq.error.ZMQError: Socket operation on non-socket

During handling of the above exception, another exception occurred:

Traceback (most recent call last):
  File "/opt/anaconda3/envs/smai_env/lib/python3.12/site-packages/wandb/agents/pyagent.py", line 306, in _run_job
    self._function()
  File "/var/folders/fp/g6h334cs71j2vl505scsq0dh0000gn/T/ipykernel_56530/314847199.py", line 2, in sweep_train
    with wandb.init() as run:
  File "/opt/anaconda3/envs/smai_env/lib/python3.12/site-packages/wandb/sdk/wandb_run.py", line 3679, in __exit__
    traceback.print_exception(exc_type, exc_val, exc_tb)
  File "/opt/anaconda3/envs/smai_env/lib/python3.12/traceback.py", line 125, in print_exception
    te.print(file=file, chain=chain)
  File "/opt/anaconda3/envs/smai_env/lib/python3.12/traceback.py", line 1050, in print
    print(line, file=file, end="")
  File "/opt/anaconda3/envs/smai_env/lib/python3.12/site-packages/wandb/sdk/lib/redirect.py", line 645, in write
    self._old_write(data)
  File "/opt/anaconda3/envs/smai_env/lib/python3.12/site-packages/ipykernel/iostream.py", line 694, in write
    self._schedule_flush()
  File "/opt/anaconda3/envs/smai_env/lib/python3.12/site-packages/ipykernel/iostream.py", line 590, in _schedule_flush
    self.pub_thread.schedule(_schedule_in_thread)
  File "/opt/anaconda3/envs/smai_env/lib/python3.12/site-packages/ipykernel/iostream.py", line 267, in schedule
    self._event_pipe.send(b"")
  File "/opt/anaconda3/envs/smai_env/lib/python3.12/site-packages/zmq/sugar/socket.py", line 696, in send
    return super().send(data, flags=flags, copy=copy, track=track)
           ^^^^^^^^^^^^^^^^^^^^^^^^^^^^^^^^^^^^^^^^^^^^^^^^^^^^^^^
  File "zmq/backend/cython/socket.pyx", line 742, in zmq.backend.cython.socket.Socket.send
  File "zmq/backend/cython/socket.pyx", line 783, in zmq.backend.cython.socket.Socket.send
  File "zmq/backend/cython/socket.pyx", line 138, in zmq.backend.cython.socket._check_closed
zmq.error.ZMQError: Socket operation on non-socket

During handling of the above exception, another exception occurred:

Traceback (most recent call last):
  File "/opt/anaconda3/envs/smai_env/lib/python3.12/site-packages/wandb/sdk/wandb_run.py", line 2438, in _atexit_cleanup
    self._on_finish()
  File "/opt/anaconda3/envs/smai_env/lib/python3.12/site-packages/wandb/sdk/wandb_run.py", line 2688, in _on_finish
    _ = exit_handle.wait(
        ^^^^^^^^^^^^^^^^^
  File "/opt/anaconda3/envs/smai_env/lib/python3.12/site-packages/wandb/sdk/lib/mailbox.py", line 298, in wait
    on_probe(probe_handle)
  File "/opt/anaconda3/envs/smai_env/lib/python3.12/site-packages/wandb/sdk/wandb_run.py", line 2647, in _on_probe_exit
    result = handle.wait(timeout=0, release=False)
             ^^^^^^^^^^^^^^^^^^^^^^^^^^^^^^^^^^^^^
  File "/opt/anaconda3/envs/smai_env/lib/python3.12/site-packages/wandb/sdk/lib/mailbox.py", line 281, in wait
    raise MailboxError("transport failed")
wandb.sdk.lib.mailbox.MailboxError: transport failed
2024-11-02 17:43:02,337 INFO    Thread-30 (_run_job):56530 [wandb_init.py:init():867] starting run threads in backend
2024-11-02 17:43:02,431 INFO    Thread-30 (_run_job):56530 [wandb_run.py:_console_start():2463] atexit reg
2024-11-02 17:43:02,431 INFO    Thread-30 (_run_job):56530 [wandb_run.py:_redirect():2311] redirect: wrap_raw
2024-11-02 17:43:02,431 INFO    Thread-30 (_run_job):56530 [wandb_run.py:_redirect():2376] Wrapping output streams.
2024-11-02 17:43:02,431 INFO    Thread-30 (_run_job):56530 [wandb_run.py:_redirect():2401] Redirects installed.
2024-11-02 17:43:02,432 INFO    Thread-30 (_run_job):56530 [wandb_init.py:init():911] run started, returning control to user process
2024-11-02 18:10:28,886 INFO    MainThread:56530 [jupyter.py:save_ipynb():387] not saving jupyter notebook
2024-11-02 18:10:28,900 INFO    MainThread:56530 [wandb_init.py:_pause_backend():445] pausing backend
2024-11-02 18:12:46,710 INFO    MainThread:56530 [wandb_init.py:_resume_backend():450] resuming backend
2024-11-02 18:12:46,742 INFO    MainThread:56530 [jupyter.py:save_ipynb():387] not saving jupyter notebook
2024-11-02 18:12:46,768 INFO    MainThread:56530 [wandb_init.py:_pause_backend():445] pausing backend
2024-11-02 18:12:47,967 INFO    MainThread:56530 [wandb_init.py:_resume_backend():450] resuming backend
